Workbook

Sheet README
A1: Building Material Quantity Calculator
A3: Purpose | B3: Calculates approximate material quantities for a building from a single input: Built-up (covered/plinth) Area in sqft. All thumb-rule constants are sourced from the uploaded 'Thumb_rules_converted_260831.xlsx' workbook (Pages 1-5, 9-13 only; Pages 6-8 excluded per instruction, as those are cost/percentage tables, not physical quantities).
A5: How to use | B5: 1. Go to the 'Inputs' sheet. 2. Enter your Built-up Area in sqft in the yellow cell. 3. Choose Wall System from the dropdown. 4. Review/adjust the two loose-volume factors if you have site-specific data. 5. All results appear automatically on 'Quantity_Calculation'.
A7: Colour legend | B7: Yellow fill = your input cell (edit these). Blue text = a sourced constant, taken verbatim/derived from the source workbook (see 'Sourced_Constants' sheet for exact cell citations). Black text = a live formula. Orange fill = manual-entry cell with NO source in the thumb-rule workbook (Plumbing & Electrical sheet).
A9: No hardcoded results | B9: Every quantity on 'Quantity_Calculation' is a formula referencing 'Inputs' and 'Sourced_Constants' - change the built-up area or wall system and every figure recalculates.
A11: Sheets in this workbook | B11: 1. README (this sheet) 2. Inputs 3. Sourced_Constants (full citation table) 4. Quantity_Calculation (main output) 5. Plumbing_Electrical_Provisional (manual entry - no source exists) 6. Notes_Assumptions (methodology, caveats, items NOT covered)
A13: Compatibility | B13: Built with plain arithmetic and IF() formulas only - no dynamic array or post-2007 functions - compatible with Microsoft Office 2007 (.xlsx).

Sheet Inputs
A1: INPUTS
A2: Built-up Area (sqft) | B2: 1000 | C2: << ENTER YOUR VALUE HERE. Example value shown = 1000 sqft.
A3: Built-up Area (sqm) | B3: =B2/10.7639 -> 92.90313 | C3: Conversion factor 10.7639 sqft/sqm (real unit conversion).
A4: Wall System | B4: Block (15cm) | C4: Block (15cm) = Table 14.2 block-work system (Page_3). Brick (23cm) = Table 14.3 23cm brick-wall system (Page_5). See Notes_Assumptions for how this mapping was decided.
A5: Excavation loose-volume factor | B5: 1.45 | C5: CPWD DAR benchmark range is 1.40-1.50 (Page_11, I3). Sheet's own field-practice figure (Page_10, A5/D5) is 1.50. Default set to 1.45 (mid-band); edit if you have site data.
A6: Backfill (plinth filling) loose-volume factor | B6: 1.3 | C6: CPWD DAR benchmark range is 1.25-1.35 (Page_11, I4). Sheet's own field-practice figure (Page_10, A6/D6) is 1.50. Default set to 1.30 (mid-band); edit if you have site data.

Sheet Sourced_Constants
A1: Item | B1: Category | C1: Value - Block System | D1: Value - Brick System | E1: Unit | F1: Source Sheet | G1: Source Cell | H1: Note
A2: EARTHWORK
A3: Excavation (pit, compacted) | B3: Earthwork | C3: 0.31 | D3: 0.31 | E3: cum/sqm | F3: Page_13 | G3: C41 | H3: Table 14.15
A4: Rubble - plinth soling | B4: Earthwork | C4: 0.06 | D4: 0.06 | E4: cum/sqm | F4: Page_3 | G4: D24 | H4: Table 14.2
A5: Murum - plinth filling (compacted) | B5: Earthwork | C5: 0.23 | D5: 0.23 | E5: cum/sqm | F5: Page_3 | G5: D26 | H5: Table 14.2
A6: CONCRETE (RCC)
A7: RCC below plinth (footing) | B7: Concrete | C7: 0.046 | D7: 0.046 | E7: cum/sqm | F7: Page_13 | G7: C42 | H7: Table 14.15
A8: RCC above plinth (columns/beams/slab) | B8: Concrete | C8: 0.29 | D8: 0.29 | E8: cum/sqm | F8: Page_13 | G8: C43 | H8: Table 14.15
A9: Cement rate for M20 nominal mix | B9: Concrete | C9: 6.4 | D9: 6.4 | E9: bags/cum | F9: Page_3 | G9: G5 (cited) | H9: Sheet's own citation text states this rate for M15-M20
A10: Aggregate (Metal) for RCC | B10: Concrete | C10: 0.27 | D10: 0.27 | E10: cum/sqm | F10: Page_3 | G10: D22 | H10: Table 14.2; Table 14.3 states other materials same as 14.2
A11: Sand for RCC (component, cross-check only) | B11: Concrete | C11: 0.21 | D11: 0.22 | E11: cum/sqm | F11: Page_3 / Page_5 | G11: D13 / D11 | H11: Not used directly - Sand Total row below is the sourced total
A12: CEMENT (masonry / plaster / other)
A13: Cement - Masonry | B13: Cement | C13: 0.43 | D13: 0.86 | E13: bags/sqm | F13: Page_3 / Page_5 | G13: D6 / D6 | H13: Table 14.2 / 14.3
A14: Cement - Plastering | B14: Cement | C14: 1.18 | D14: 1.61 | E14: bags/sqm | F14: Page_3 / Page_5 | G14: D7 / D7 | H14: Table 14.2 / 14.3
A15: Cement - Others (flooring/dado bedding) | B15: Cement | C15: 0.32 | D15: 0.33 | E15: bags/sqm | F15: Page_3 / Page_5 | G15: D8 / D8 | H15: Table 14.2 / 14.3
A16: SAND
A17: Sand - Total | B17: Sand | C17: 0.72 | D17: 0.91 | E17: cum/sqm | F17: Page_3 / Page_5 | G17: D20 / D18 | H17: Table 14.2 / 14.3 (all-trades total)
A18: MASONRY - BRICKS / BLOCKS
A19: Bricks - Plinth (applies to both systems) | B19: Masonry | C19: 43 | D19: 43 | E19: Nos/sqm | F19: Page_3 | G19: D28 | H19: Table 14.2 - plinth brickwork used regardless of wall system
A20: Blocks - Wall (Block system only) | B20: Masonry | C20: 27.5 | D20: 0 | E20: Nos/sqm | F20: Page_3 | G20: D39 | H20: Table 14.2 - N/A for brick system (set to 0)
A21: Bricks - Wall, ext+int (Brick system only) | B21: Masonry | C21: 0 | D21: 129 | E21: Nos/sqm | F21: Page_5 | G21: D21+D22 | H21: 86+43=129, matches D23 Total (172) minus D20 plinth (43)
A22: STEEL (Table 14.14)
A23: Steel - Footing | B23: Steel | C23: 0.55 | D23: 0.55 | E23: kg/sqm | F23: Page_13 | G23: C25 | H23: Table 14.14
A24: Steel - Columns up to plinth | B24: Steel | C24: 2.15 | D24: 2.15 | E24: kg/sqm | F24: Page_13 | G24: C26 | H24: Table 14.14
A25: Steel - Tie beam | B25: Steel | C25: 1.15 | D25: 1.15 | E25: kg/sqm | F25: Page_13 | G25: C27 | H25: Table 14.14
A26: Steel - Columns (superstructure) | B26: Steel | C26: 4.8 | D26: 4.8 | E26: kg/sqm | F26: Page_13 | G26: C28 | H26: Table 14.14
A27: Steel - Slab | B27: Steel | C27: 7 | D27: 7 | E27: kg/sqm | F27: Page_13 | G27: C29 | H27: Table 14.14
A28: Steel - Beam | B28: Steel | C28: 7.5 | D28: 7.5 | E28: kg/sqm | F28: Page_13 | G28: C30 | H28: Table 14.14
A29: Steel - Chajja/loft/lintel | B29: Steel | C29: 0.55 | D29: 0.55 | E29: kg/sqm | F29: Page_13 | G29: C31 | H29: Table 14.14
A30: Steel - Overhead water tank | B30: Steel | C30: 0.55 | D30: 0.55 | E30: kg/sqm | F30: Page_13 | G30: C32 | H30: Table 14.14
A31: PLASTER
A32: Plaster - Internal (area) | B32: Plaster | C32: 3.2 | D32: 3.2 | E32: sqm/sqm | F32: Page_13 | G32: C46 | H32: Table 14.15
A33: Plaster - External (area) | B33: Plaster | C33: 2.5 | D33: 2.5 | E33: sqm/sqm | F33: Page_13 | G33: C47 | H33: Table 14.15
A34: Sanla / lime punning finish | B34: Plaster | C34: 0.27 | D34: 0.27 | E34: bags/sqm | F34: Page_3 | G34: D43 | H34: LIME ITEM - see Notes_Assumptions
A35: FLOORING & TILING
A36: Lime - flooring bedding | B36: Flooring | C36: 0.16 | D36: 0.16 | E36: bags/sqm | F36: Page_3 | G36: D44 | H36: LIME ITEM - see Notes_Assumptions
A37: Tiles - Rooms/Balcony (mosaic) | B37: Flooring | C37: 0.75 | D37: 0.75 | E37: sqm/sqm | F37: Page_3 | G37: D47 | H37: Table 14.2
A38: Tiles - Bath/Toilet floor | B38: Flooring | C38: 0.05 | D38: 0.05 | E38: sqm/sqm | F38: Page_4 | G38: D6 | H38: Table 14.2 (Part 2)
A39: Tiles - Dado Bath/WC (total) | B39: Flooring | C39: 0.2 | D39: 0.2 | E39: sqm/sqm | F39: Page_4 | G39: D10 | H39: Table 14.2 (Part 2)
A40: Tiles - Parking (chequered) | B40: Flooring | C40: 0.15 | D40: 0.15 | E40: sqm/sqm | F40: Page_4 | G40: D13 | H40: Table 14.2 (Part 2)
...

Sheet Quantity_Calculation
A1: QUANTITY CALCULATION
A2: Item | B2: Quantity | C2: Unit | D2: Formula basis / traceability
A3: EARTHWORK
A4: Excavation - compacted pit volume | B4: =Inputs!$B$3*Sourced_Constants!$C$3 -> 28.79997 | C4: cum | D4: Sourced_Constants: Excavation (pit, compacted)
A5: Excavation - loose volume for disposal | B5: =B4*Inputs!$B$5 -> 41.759957 | C5: cum | D5: Compacted vol x Inputs!Excavation loose factor (Page_10 A5 / Page_11 I3)
A6: Rubble - plinth soling | B6: =Inputs!$B$3*Sourced_Constants!$C$4 -> 5.5741878 | C6: cum | D6: Sourced_Constants: Rubble - plinth soling
A7: Murum - plinth filling, compacted | B7: =Inputs!$B$3*Sourced_Constants!$C$5 -> 21.36772 | C7: cum | D7: Sourced_Constants: Murum - plinth filling (compacted)
A8: Murum - plinth filling, loose (to procure) | B8: =B7*Inputs!$B$6 -> 27.778036 | C8: cum | D8: Compacted vol x Inputs!Backfill loose factor (Page_10 A6 / Page_11 I4)
A9: CONCRETE (RCC)
A10: RCC below plinth (footing concrete) | B10: =Inputs!$B$3*Sourced_Constants!$C$7 -> 4.273544 | C10: cum | D10: Sourced_Constants: RCC below plinth (footing)
A11: RCC above plinth (columns+beams+slab) | B11: =Inputs!$B$3*Sourced_Constants!$C$8 -> 26.941908 | C11: cum | D11: Sourced_Constants: RCC above plinth (columns/beams/slab)
A12: RCC - Total | B12: =B10+B11 -> 31.215452 | C12: cum | D12: Sum of above two rows
A13: Aggregate (coarse) for RCC | B13: =Inputs!$B$3*Sourced_Constants!$C$10 -> 25.083845 | C13: cum | D13: Sourced_Constants: Aggregate (Metal) for RCC
A14: CEMENT (M20 baseline)
A15: Cement - for RCC (M20 basis) | B15: =(B10+B11)*Sourced_Constants!$C$9 -> 199.77889 | C15: bags | D15: (RCC below+above plinth vol) x 6.4 bags/cum (Page_3 G5 cited rate) - see Notes_Assumptions for M20 derivation
A16: Cement - for Masonry | B16: =Inputs!$B$3*IF(Inputs!$B$4="Block (15cm)",Sourced_Constants!$C$13,Sourced_Constants!$D$13) -> 39.948346 | C16: bags | D16: Sourced_Constants: Cement - Masonry (wall-system dependent)
A17: Cement - for Plastering | B17: =Inputs!$B$3*IF(Inputs!$B$4="Block (15cm)",Sourced_Constants!$C$14,Sourced_Constants!$D$14) -> 109.62569 | C17: bags | D17: Sourced_Constants: Cement - Plastering (wall-system dependent)
A18: Cement - for Others (flooring/dado bedding) | B18: =Inputs!$B$3*IF(Inputs!$B$4="Block (15cm)",Sourced_Constants!$C$15,Sourced_Constants!$D$15) -> 29.729002 | C18: bags | D18: Sourced_Constants: Cement - Others (wall-system dependent)
A19: Cement - TOTAL | B19: =B15+B16+B17+B18 -> 379.08193 | C19: bags | D19: Sum of Cement rows above (M20 baseline, per user instruction)
A20: SAND
A21: Sand - Total (all trades) | B21: =Inputs!$B$3*IF(Inputs!$B$4="Block (15cm)",Sourced_Constants!$C$17,Sourced_Constants!$D$17) -> 66.890254 | C21: cum | D21: Sourced_Constants: Sand - Total (wall-system dependent)
A22: MASONRY - BRICKS / BLOCKS
A23: Bricks - Plinth masonry | B23: =Inputs!$B$3*Sourced_Constants!$C$19 -> 3994.8346 | C23: Nos | D23: Sourced_Constants: Bricks - Plinth (applies to both systems)
A24: Blocks - Wall (if Block system selected) | B24: =Inputs!$B$3*IF(Inputs!$B$4="Block (15cm)",Sourced_Constants!$C$20,Sourced_Constants!$D$20) -> 2554.8361 | C24: Nos | D24: IF(Inputs wall system = Block, Sourced_Constants C20, else D20). Shows 0 automatically when Brick is selected.
A25: Bricks - Wall, ext+int (if Brick system selected) | B25: =Inputs!$B$3*IF(Inputs!$B$4="Block (15cm)",Sourced_Constants!$C$21,Sourced_Constants!$D$21) -> 0 | C25: Nos | D25: IF(Inputs wall system = Block, Sourced_Constants C21, else D21). Shows 0 automatically when Block is selected.
A26: STEEL (Table 14.14)
A27: Steel - Footing | B27: =Inputs!$B$3*Sourced_Constants!$C$23 -> 51.096721 | C27: kg | D27: Sourced_Constants: Steel - Footing
A28: Steel - Columns up to plinth | B28: =Inputs!$B$3*Sourced_Constants!$C$24 -> 199.74173 | C28: kg | D28: Sourced_Constants: Steel - Columns up to plinth
A29: Steel - Tie beam | B29: =Inputs!$B$3*Sourced_Constants!$C$25 -> 106.8386 | C29: kg | D29: Sourced_Constants: Steel - Tie beam
A30: Steel - Columns (superstructure) | B30: =Inputs!$B$3*Sourced_Constants!$C$26 -> 445.93502 | C30: kg | D30: Sourced_Constants: Steel - Columns (superstructure)
A31: Steel - Slab | B31: =Inputs!$B$3*Sourced_Constants!$C$27 -> 650.32191 | C31: kg | D31: Sourced_Constants: Steel - Slab
A32: Steel - Beam | B32: =Inputs!$B$3*Sourced_Constants!$C$28 -> 696.77347 | C32: kg | D32: Sourced_Constants: Steel - Beam
A33: Steel - Chajja/loft/lintel | B33: =Inputs!$B$3*Sourced_Constants!$C$29 -> 51.096721 | C33: kg | D33: Sourced_Constants: Steel - Chajja/loft/lintel
A34: Steel - Overhead water tank | B34: =Inputs!$B$3*Sourced_Constants!$C$30 -> 51.096721 | C34: kg | D34: Sourced_Constants: Steel - Overhead water tank
A35: Steel - TOTAL | B35: =B27+B28+B29+B30+B31+B32+B33+B34 -> 2252.9009 | C35: kg | D35: Sum of Steel rows above
A36: PLASTER
A37: Plaster - Internal (area) | B37: =Inputs!$B$3*Sourced_Constants!$C$32 -> 297.29002 | C37: sqm | D37: Sourced_Constants: Plaster - Internal (area)
A38: Plaster - External (area) | B38: =Inputs!$B$3*Sourced_Constants!$C$33 -> 232.25782 | C38: sqm | D38: Sourced_Constants: Plaster - External (area)
A39: Sanla / lime punning finish (cement) | B39: =Inputs!$B$3*Sourced_Constants!$C$34 -> 25.083845 | C39: bags | D39: Sourced_Constants: Sanla / lime punning finish - LIME ITEM, see Notes_Assumptions
A40: FLOORING & TILING
...

Sheet Plumbing_Electrical_Provisional
A1: PLUMBING & ELECTRICAL - PROVISIONAL (NO SOURCE IN THUMB-RULE WORKBOOK)
A2: Item | B2: Quantity (fill in manually) | C2: Unit | D2: Note
A3: This entire sheet is a placeholder. The source workbook gives only qualitative specifications for plumbing (Page_2, C23/D23) and electrical work (Page_2, C24/D24) - no per-sqm quantity constant exists anywhere in Pages 1-13 for these trades. Every orange cell below is blank on purpose - do NOT treat a blank as zero. Fill in from your own drawings/BOQ; nothing here is calculated or sourced.
A5: PLUMBING
A6: GI pipe - running length (water supply) | D6: No source in workbook - manual entry
A7: CPVC/UPVC pipe - running length (water supply) | D7: No source in workbook - manual entry
A8: PVC-SWR pipe - running length (drainage) | D8: No source in workbook - manual entry
A9: W.C. (water closet) - count | D9: No source in workbook - manual entry
A10: Wash basin - count | D10: No source in workbook - manual entry
A11: Kitchen sink - count | D11: No source in workbook - manual entry
A12: CP fittings (taps, mixers, showers) - count | D12: No source in workbook - manual entry
A13: Stop cocks / valves - count | D13: No source in workbook - manual entry
A14: Overhead tank - capacity (litres) | D14: No source in workbook - manual entry
A15: Underground sump - capacity (litres) | D15: No source in workbook - manual entry
A16: ELECTRICAL
A17: Conduit (PVC/FRLS) - running length | D17: No source in workbook - manual entry
A18: Copper wire - running length (by gauge) | D18: No source in workbook - manual entry
A19: Light points - count | D19: No source in workbook - manual entry
A20: Fan points - count | D20: No source in workbook - manual entry
A21: Plug/socket points (5A) - count | D21: No source in workbook - manual entry
A22: Plug/socket points (15A) - count | D22: No source in workbook - manual entry
A23: Distribution board (DB) - count / rating | D23: No source in workbook - manual entry
A24: MCB/RCCB - count | D24: No source in workbook - manual entry
A25: Switchboard/switch plates - count | D25: No source in workbook - manual entry
A26: Earthing - count of pits | D26: No source in workbook - manual entry

Sheet Notes_Assumptions
A1: NOTES, ASSUMPTIONS & ITEMS NOT COVERED
A3: Source sheets used | B3: Pages 1-5 and 9-13 of the uploaded Thumb_rules_converted_260831.xlsx. Pages 6, 7, and 8 were excluded per instruction (they are cost/percentage tables - e.g. plinth area rate money values, material cost-share percentages - not physical material quantities, and several of their CPWD/IS citations were found to be inaccurate during an earlier audit of this workbook).
A4: Cement - M20 baseline derivation | B4: The source sheet's raw 'Cement for RCC' figure (Page_3, D5 = 1.94 bags/sqm) is stated against an M15 nominal mix (Page_2, C13). Per your instruction to use M20 as baseline, this workbook instead computes: (RCC below plinth + RCC above plinth, cum/sqm, Page_13 C42+C43) x 6.4 bags/cum. The 6.4 bags/cum rate is the exact figure the source sheet's own citation states for the M15-M20 range (Page_3, G5: '@ 6.4 bags/cum (M15-M20)'). The result (2.15 bags/sqm for RCC alone) was cross-checked and falls inside CPWD's own published M20 benchmark band for total cement (Page_3, F9: '4.10-4.50 bags/sqm for M20'), once masonry+plaster+other cement is added. This was NOT taken from a single sourced cell - it is a derived calculation from two other sourced cells, and is computed live by formula in Quantity_Calculation, not hardcoded.
A5: Wall system mapping (Block vs Brick) | B5: Your two options map to two different tables in the source workbook: 'Block (15cm)' = Table 14.2's block-work figures (Page_3), which is the table's primary basis; 'Brick (23cm)' = Table 14.3 (Page_5), a wholly separate 23cm-thick brick wall system with its own cement/sand/brick totals. Note Table 14.2 (Page_3) ALSO lists brick options for a 15cm-thick wall (rows 28-35) as an alternate to blocks within the same wall thickness - those 15cm brick figures are NOT used by this calculator's Brick option, since you asked for a binary block-vs-brick choice and Table 14.3's 23cm brick system is the workbook's only fully self-contained brick-specific table (own cement, sand, and brick-count totals, not mixed with block figures).
A6: Plinth bricks - applies regardless of wall system | B6: Page_3's plinth brickwork line (D28 = 43 Nos/sqm) is added for BOTH wall systems, since the source workbook gives no block-based alternative for plinth masonry - only bricks are shown for this specific item in Table 14.2.
A7: Lime items - flagged, not removed or replaced | B7: Two lime-consuming line items exist in the source data: Sanla/lime punning finish (Page_3, D43 = 0.27 bags/sqm) and Lime for flooring bedding (Page_3, D44 = 0.16 bags/sqm). Per your note that modern construction commonly no longer uses lime, both rows remain in Quantity_Calculation (since removing sourced data would be fabrication) but are labeled 'LIME ITEM' in the traceability column. No cement or plasticizer substitute figure has been added, because no sourced replacement constant exists in the workbook - verify current site/vendor practice before ordering against these two rows.
A8: Plastering - flat average used, not spec-selectable | B8: Per your instruction, the plastering cement figure uses the flat Table 14.2/14.3 average (Block: 1.18 bags/sqm, Brick: 1.61 bags/sqm) rather than the more granular Page_12 (Table 14.10, Part E) spec-by-spec rates (Sanla 12.5mm/20mm, sand-faced single/double coat, each at 3 different mix ratios). Those Page_12 rates remain unused in this workbook.
A9: Excavation & backfill - loose-volume factors | B9: The source workbook gives two different multipliers for converting compacted volume to loose (procurement) volume: the sheet's own stated field-practice figure (Page_10, A5/A6: 1.5x for both excavation and backfill) versus CPWD's own DAR benchmark range (Page_11, I3: 1.40-1.50x for excavation; I4: 1.25-1.35x for backfill). This workbook defaults to the CPWD DAR mid-band values (1.45 and 1.30 respectively) as EDITABLE inputs on the Inputs sheet, not hardcoded - change them if you want to match the sheet's own 1.5x field-practice figure instead.
A10: Paint multiplying factors | B10: Sourced from the sheet's own stated factors (Page_10, A30: Flush door 2.25x, M.S. window 1.5x), not the slightly different CPWD citation column figures on the same row (Page_10, C30: Flush door 2.0x, M.S. window 1.5x) - the sheet's own original data column was used for consistency with the rest of the calculator, which sources from original-data columns throughout, not citation columns.
A11: Items with NO source anywhere in the workbook | B11: Plumbing and electrical quantities (see Plumbing_Electrical_Provisional sheet - manual entry only). Beyond those, the following are also absent from every page of the source workbook and are NOT included anywhere in this calculator: damp-proof course (DPC), anti-termite treatment, PCC blinding/bed layer under footings (may or may not be folded into the 'RCC below plinth' figure - unclear from the source), compound/boundary wall, gate, external paving, site development and landscaping (explicitly excluded by the source book's own scope note, Page_2 A4), sanitary fixture counts, lift/elevator, fire-fighting systems, false ceiling/POP (mentioned only qualitatively in the source, Page_2 D16, with no quantity constant), waterproofing chemical/admixture dosage (mentioned qualitatively only), parapet wall/terrace railing (may or may not be included within 'External Masonry 0.9 sqm/sqm' - unclear from source), the overhead tank's own RCC/concrete volume (only its steel is quantified in the source, at 0.55 kg/sqm), and any structural roof truss/steel roofing system (source assumes RCC-framed construction throughout).
A12: Compatibility | B12: All formulas use only SUM, IF, and basic arithmetic operators - no dynamic array or post-2007 functions - for Microsoft Office 2007 (.xlsx) compatibility.
