Workbook

Sheet Project Summary & BOQ
A1: 🏗️ 3-TIER VERIFIED CIVIL COST, MATERIAL & MANPOWER ESTIMATE (BOQ)
A3: 1. PROJECT SCOPE & QUALITY PARAMETERS
A4: Project Name / Location: | D4: Standard Residential House / Commercial Building
A5: Construction Quality Tier: | D5: Standard
A6: Total Built-up Area (Sq Ft): | D6: 1500
A7: Equivalent Area (Sq M): | D7: =D6*0.09290304 -> 139.35456
A8: Quality Tier Benchmark Rate (₹ / sq ft): | D8: =IF(D5="Basic", 'Settings & Rates'!B5, IF(D5="Premium", 'Settings & Rates'!B7, 'Settings & Rates'!B6)) -> 1800
A10: 2. 3-TIER RECONCILIATION & 5% CONVERGENCE ENGINE
A11: Model Level | B11: Estimation Model Description | C11: Calculated Cost (₹) | D11: Cost / Sq Ft (₹) | E11: Mean Budget (₹) | F11: Variance (%) | G11: Status
A12: Tier 1 | B12: C₁: Bottom-Up Material + Explicit Manpower Schedule | C12: ='Material Schedule (Tier 1)'!H17 + 'Manpower & Labor (Tier 1)'!I16 -> 2853659.7 | D12: =C12/$D$6 -> 1902.4398 | E12: =$C$15 -> 2737957.4 | F12: =ABS(C12-E12)/E12 -> 0.042258619 | G12: =IF(F12<='Settings & Rates'!B57, "✔️ CONVERGED", "⚠️ DIVERGENT") -> ✔️ CONVERGED
A13: Tier 2 | B13: C₂: Meso Work-Packages Model (Civil + Finish + MEP + 10% COP) | C13: ='Trade Packages (Tier 2)'!F14 -> 2660212.5 | D13: =C13/$D$6 -> 1773.475 | E13: =$C$15 -> 2737957.4 | F13: =ABS(C13-E13)/E13 -> 0.028395219 | G13: =IF(F13<='Settings & Rates'!B57, "✔️ CONVERGED", "⚠️ DIVERGENT") -> ✔️ CONVERGED
A14: Tier 3 | B14: C₃: Macro Quality Tier Benchmark Model | C14: =D6*D8 -> 2700000 | D14: =C14/$D$6 -> 1800 | E14: =$C$15 -> 2737957.4 | F14: =ABS(C14-E14)/E14 -> 0.0138634 | G14: =IF(F14<='Settings & Rates'!B57, "✔️ CONVERGED", "⚠️ DIVERGENT") -> ✔️ CONVERGED
A15: 3-TIER RECONCILED MEAN PROJECT BUDGET (₹): | C15: =AVERAGE(C12:C14) -> 2737957.4 | D15: =C15/D6 -> 1825.3049 | E15: Max Variance: | F15: =MAX(F12:F14) -> 0.042258619 | G15: =IF(F15<='Settings & Rates'!B57, "✔️ VERIFIED", "⚠️ AUDIT REQUIRED") -> ✔️ VERIFIED
A17: 3. PRIMARY COST BIFURCATION (MATERIAL + MANPOWER)
A18: Cost Component | B18: Component Description | C18: Total Cost (₹) | D18: Cost / Sq Ft (₹) | E18: Share of C₁ (%) | F18: Key Metrics / Scope | G18: Audit Status
A19: 🧱 Material Component | B19: Steel, Cement, Bricks, Sand, Aggregates, Tiles, Paint, MEP & Joinery | C19: ='Material Schedule (Tier 1)'!H17 -> 2233709.5 | D19: =C19/$D$6 -> 1489.1397 | E19: =C19/$C$21 -> 0.7827526 | F19: 11 Material Categories | G19: ✔️ Formula Linked
A20: 👷 Manpower / Labor Component | B20: 9 Trade Crews (Masons, Barbenders, Carpenters, Painters, MEP) + JCB Excavation | C20: ='Manpower & Labor (Tier 1)'!I16 -> 619950.16 | D20: =C20/$D$6 -> 413.30011 | E20: =C20/$C$21 -> 0.2172474 | F20: ='Manpower & Labor (Tier 1)'!G16 & " mandays" -> 753.567205262079 mandays | G20: ='Manpower & Labor (Tier 1)'!G23 -> ⚠️ AUDIT REQUIRED
A21: COMBINED TIER 1 DIRECT COST (₹): | C21: =SUM(C19:C20) -> 2853659.7 | D21: =C21/D6 -> 1902.4398 | E21: 100.0% | F21: Material:Labor Ratio -> | G21: =TEXT(E19*100, "0") & " : " & TEXT(E20*100, "0") -> 78 : 22
A23: 4. TRADE PACKAGE BREAKDOWN & CONTRACTOR OVERHEAD (TIER 2)
A24: Pkg No. | B24: Trade Package Name | C24: Package Cost (₹) | D24: Cost / Sq Ft (₹) | E24: Share (%) | F24: Linked Schedule | G24: Verification
A25: 1 | B25: Civil Work Structure (Foundation, RCC, Formwork) | C25: ='Trade Packages (Tier 2)'!F6 -> 1126875 | D25: =C25/$D$6 -> 751.25 | E25: =C25/$C$32 -> 0.42360338 | F25: Tier 2 Pkg 1 | G25: ✔️ Reconciled
A26: 2 | B26: Finishing Works (Flooring, Paint, Plaster, POP) | C26: ='Trade Packages (Tier 2)'!F7 -> 701250 | D26: =C26/$D$6 -> 467.5 | E26: =C26/$C$32 -> 0.26360676 | F26: Tier 2 Pkg 2 | G26: ✔️ Reconciled
A27: 3 | B27: Electrical Wiring, Switches & Conduit | C27: ='Trade Packages (Tier 2)'!F8 -> 199500 | D27: =C27/$D$6 -> 133 | E27: =C27/$C$32 -> 0.074994009 | F27: Tier 2 Pkg 3 | G27: ✔️ Reconciled
A28: 4 | B28: Plumbing, Sanitaryware & Drainage | C28: ='Trade Packages (Tier 2)'!F9 -> 189000 | D28: =C28/$D$6 -> 126 | E28: =C28/$C$32 -> 0.071046956 | F28: Tier 2 Pkg 4 | G28: ✔️ Reconciled
A29: 5 | B29: Fire Fighting & Safety Provisions | C29: ='Trade Packages (Tier 2)'!F10 -> 60000 | D29: =C29/$D$6 -> 40 | E29: =C29/$C$32 -> 0.022554589 | F29: Tier 2 Pkg 5 | G29: ✔️ Reconciled
A30: 6 | B30: External Development & Landscaping | C30: ='Trade Packages (Tier 2)'!F11 -> 141750 | D30: =C30/$D$6 -> 94.5 | E30: =C30/$C$32 -> 0.053285217 | F30: Tier 2 Pkg 6 | G30: ✔️ Reconciled
A31: 7 | B31: Contractor Overhead & Profit (COP 10%) | C31: ='Trade Packages (Tier 2)'!F13 -> 241837.5 | D31: =C31/$D$6 -> 161.225 | E31: =C31/$C$32 -> 0.090909091 | F31: 10% on Direct | G31: ✔️ Standard Margin
A32: TOTAL TRADE PACKAGE ESTIMATE (₹): | C32: =SUM(C25:C31) -> 2660212.5 | D32: =C32/D6 -> 1773.475 | E32: 100.0% | F32: Tier 2 Model Status -> | G32: ✔️ 100% Balanced

Sheet Material Schedule (Tier 1)
A1: 🧱 TIER 1 - EMPIRICAL MATERIAL QUANTITY & COST SCHEDULE
A3: Project Built-up Area (Sq Ft): | B3: ='Project Summary & BOQ'!D6 -> 1500 | C3: Area (Sq M): | D3: =B3*'Settings & Rates'!$B$61 -> 139.35456
A5: Item No. | B5: Material Description | C5: Thumb Rule Factor | D5: Base Unit | E5: Calculated Quantity | F5: Unit | G5: Unit Rate (₹) | H5: Total Cost (₹)
A6: 1 | B6: Structural Steel (TMT Fe500) | C6: Member-wise % of concrete volume | D6: Sq Ft | E6: =('Project Summary & BOQ'!D6*'Settings & Rates'!$B$62)*('Settings & Rates'!$B$63*'Settings & Rates'!$B$67 + 'Settings & Rates'!$B$64*'Settings & Rates'!$B$68 + 'Settings & Rates'!$B$65*'Settings & Rates'!$B$69 + 'Settings & Rates'!$B$66*'Settings & Rates'!$B$70)*'Settings & Rates'!$B$71 -> 6689.3775 | F6: kg | G6: ='Settings & Rates'!B21 -> 65 | H6: =E6*G6 -> 434809.54
A7: 2 | B7: Cement (OPC/PPC 50kg Bags) | C7: RCC (8/m³) + Brick (1.26/m³) + Plaster (0.11/m²) + Tile (0.25/m²) | D7: Sq Ft | E7: =ROUND(('Project Summary & BOQ'!D6*'Settings & Rates'!$B$62*'Settings & Rates'!$B$73) + (('Project Summary & BOQ'!D6*'Settings & Rates'!$B$77/'Settings & Rates'!$B$78)*'Settings & Rates'!$B$74) + (('Project Summary & BOQ'!D6*'Settings & Rates'!$B$81*'Settings & Rates'!$B$61)*'Settings & Rates'!$B$75) + (('Project Summary & BOQ'!D6*'Settings & Rates'!$B$61)*'Settings & Rates'!$B$76), 0) -> 605 | F7: Bags | G7: ='Settings & Rates'!B22 -> 380 | H7: =E7*G7 -> 229900
A8: 3 | B8: Formwork / Shuttering Ply & Props | C8: 2.40 m² shuttering per m² plinth | D8: Sq Ft | E8: =('Project Summary & BOQ'!D6*'Settings & Rates'!$B$72) -> 3600 | F8: sq ft | G8: ='Settings & Rates'!B27 -> 60 | H8: =E8*G8 -> 216000
A9: 4 | B9: Common Red Clay Bricks | C9: 18 Bricks per sq ft built-up | D9: Sq Ft | E9: =ROUND('Project Summary & BOQ'!D6*'Settings & Rates'!$B$77, 0) -> 27000 | F9: Nos | G9: ='Settings & Rates'!B25 -> 9 | H9: =E9*G9 -> 243000
A10: 5 | B10: River / Coarse Sand | C10: 1.80 cu ft per sq ft built-up | D10: Sq Ft | E10: =ROUND('Project Summary & BOQ'!D6*'Settings & Rates'!$B$79, 0) -> 2700 | F10: cu ft | G10: ='Settings & Rates'!B23 -> 55 | H10: =E10*G10 -> 148500
A11: 6 | B11: Coarse Aggregate (20mm down) | C11: 1.35 cu ft per sq ft built-up | D11: Sq Ft | E11: =ROUND('Project Summary & BOQ'!D6*'Settings & Rates'!$B$80, 0) -> 2025 | F11: cu ft | G11: ='Settings & Rates'!B24 -> 45 | H11: =E11*G11 -> 91125
A12: 7 | B12: Electrical Conduit & Materials | C12: Conduit, Wire, DB & Switchboards | D12: Sq Ft | E12: ='Project Summary & BOQ'!D6 -> 1500 | F12: sq ft | G12: ='Settings & Rates'!B13 -> 133 | H12: =E12*G12 -> 199500
A13: 8 | B13: Plumbing & Drainage Materials | C13: CPVC/UPVC pipes, sanitary fixtures | D13: Sq Ft | E13: ='Project Summary & BOQ'!D6 -> 1500 | F13: sq ft | G13: ='Settings & Rates'!B14 -> 126 | H13: =E13*G13 -> 189000
A14: 9 | B14: Internal Wall Painting Materials | C14: Putty (2) + Primer (1) + Paint (2) | D14: Sq Ft | E14: ='Project Summary & BOQ'!D6 -> 1500 | F14: sq ft | G14: ='Settings & Rates'!B30 -> 70 | H14: =E14*G14 -> 105000
A15: 10 | B15: Flooring Tiles & Base Mortar | C15: 1.25x tiles + Rs 40/sqft base bedding | D15: Sq Ft | E15: ='Project Summary & BOQ'!D6 -> 1500 | F15: sq ft | G15: =('Settings & Rates'!$B$82*'Settings & Rates'!B26)+'Settings & Rates'!$B$83 -> 121.25 | H15: =E15*G15 -> 181875
A16: 11 | B16: Joinery, Doors & Windows | C16: Flush doors & UPVC window sets | D16: Sq Ft | E16: ='Project Summary & BOQ'!D6 -> 1500 | F16: sq ft | G16: ='Settings & Rates'!B29 -> 130 | H16: =E16*G16 -> 195000
A17: TOTAL TIER 1 MATERIAL COMPONENT COST (₹): | H17: =SUM(H6:H16) -> 2233709.5

Sheet Manpower & Labor (Tier 1)
A1: 👷 TIER 1 - DEEP TRADE MANPOWER & LABOR RECONCILIATION SCHEDULE
A3: Project Built-up Area: | B3: ='Project Summary & BOQ'!D6 -> 1500 | C3: sq ft
A5: Trade No. | B5: Activity / Trade Name | C5: Governing Scope | D5: Scope Unit | E5: Crew Output Standard | F5: Daily Crew Wage (₹) | G5: Required Mandays | H5: Trade Rate / Unit (₹) | I5: Total Labor Cost (₹)
A6: 1 | B6: Concrete Placing & Curing (RMC/Batch) | C6: ='Project Summary & BOQ'!D6*'Settings & Rates'!$B$62 -> 57 | D6: m³ | E6: 0.24 Skilled + 2.90 Unskilled / m³ | F6: =('Settings & Rates'!B45*'Settings & Rates'!B34)+('Settings & Rates'!B46*'Settings & Rates'!B40) -> 1968 | G6: =C6*('Settings & Rates'!B45+'Settings & Rates'!B46) -> 178.98 | H6: =F6 -> 1968 | I6: =C6*H6 -> 112176
A7: 2 | B7: Brick Masonry (230mm Wall) | C7: =ROUND('Project Summary & BOQ'!D6*'Settings & Rates'!$B$77,0)/'Settings & Rates'!$B$78 -> 54 | D7: m³ | E7: ='Settings & Rates'!B47 -> 1.35 | F7: ='Settings & Rates'!B34+(2*'Settings & Rates'!B40) -> 2150 | G7: =(C7/E7)*'Settings & Rates'!$B$87 -> 120 | H7: =F7/E7 -> 1592.5926 | I7: =C7*H7 -> 86000
A8: 3 | B8: Plastering (15mm Internal/External) | C8: =('Project Summary & BOQ'!D6*'Settings & Rates'!$B$81)*'Settings & Rates'!$B$61 -> 418.06368 | D8: m² | E8: ='Settings & Rates'!B48 -> 14.5 | F8: ='Settings & Rates'!B34+(2*'Settings & Rates'!B40) -> 2150 | G8: =(C8/E8)*'Settings & Rates'!$B$88 -> 86.495934 | H8: =F8/E8 -> 148.27586 | I8: =C8*H8 -> 61988.753
A9: 4 | B9: Shuttering & Formwork Erection | C9: =('Project Summary & BOQ'!D6*'Settings & Rates'!$B$61)*'Settings & Rates'!$B$72 -> 334.45094 | D9: m² | E9: ='Settings & Rates'!B49 -> 11 | F9: ='Settings & Rates'!B36+(2*'Settings & Rates'!B40) -> 2100 | G9: =(C9/E9)*'Settings & Rates'!$B$89 -> 91.213894 | H9: =F9/E9 -> 190.90909 | I9: =C9*H9 -> 63849.726
A10: 5 | B10: Steel Reinforcement Binding | C10: =ROUND(('Material Schedule (Tier 1)'!E6/1000),2) -> 6.69 | D10: MT | E10: ='Settings & Rates'!B50 -> 0.135 | F10: =(2*'Settings & Rates'!B35)+(2*'Settings & Rates'!B40) -> 3000 | G10: =(C10/E10)*'Settings & Rates'!$B$90 -> 198.22222 | H10: =F10/E10 -> 22222.222 | I10: =C10*H10 -> 148666.67
A11: 6 | B11: Flooring & Vitrified Tiling | C11: =ROUND('Project Summary & BOQ'!D6*'Settings & Rates'!$B$82,0)*'Settings & Rates'!$B$61 -> 174.1932 | D11: m² | E11: ='Settings & Rates'!B51 -> 13.5 | F11: ='Settings & Rates'!B34+(2*'Settings & Rates'!B40) -> 2150 | G11: =(C11/E11)*'Settings & Rates'!$B$91 -> 38.7096 | H11: =F11/E11 -> 159.25926 | I11: =C11*H11 -> 27741.88
A12: 7 | B12: Internal Painting (2 coats + putty) | C12: =('Project Summary & BOQ'!D6*'Settings & Rates'!$B$81)*'Settings & Rates'!$B$61 -> 418.06368 | D12: m² | E12: ='Settings & Rates'!B52 -> 28 | F12: ='Settings & Rates'!B37+'Settings & Rates'!B40 -> 1450 | G12: =(C12/E12)*'Settings & Rates'!$B$92 -> 29.861691 | H12: =F12/E12 -> 51.785714 | I12: =C12*H12 -> 21649.726
A13: 8 | B13: Electrical Chasing & Wiring Labor | C13: ='Project Summary & BOQ'!D6 -> 1500 | D13: sq ft | E13: Thumb Rule (0.23 days/100 sqft) | F13: ='Settings & Rates'!B38+'Settings & Rates'!B40 -> 1500 | G13: =(C13/100)*'Settings & Rates'!$B$93*'Settings & Rates'!$B$95 -> 3.45 | H13: ='Settings & Rates'!B53 -> 32.5 | I13: =C13*H13 -> 48750
A14: 9 | B14: Plumbing & Sanitary Fitting Labor | C14: ='Project Summary & BOQ'!D6 -> 1500 | D14: sq ft | E14: Thumb Rule (0.21 days/100 sqft) | F14: ='Settings & Rates'!B39+'Settings & Rates'!B40 -> 1500 | G14: =(C14/100)*'Settings & Rates'!$B$94*'Settings & Rates'!$B$95 -> 3.15 | H14: ='Settings & Rates'!B54 -> 29.5 | I14: =C14*H14 -> 44250
A15: 10 | B15: Machine Earthwork Excavation (JCB) | C15: =('Project Summary & BOQ'!D6*'Settings & Rates'!$B$61)*'Settings & Rates'!$B$96 -> 104.51592 | D15: m³ | E15: ='Settings & Rates'!B55 -> 30 | F15: ='Settings & Rates'!B41 -> 1400 | G15: =C15/E15 -> 3.483864 | H15: =F15/E15 -> 46.666667 | I15: =C15*H15 -> 4877.4096
A16: TOTAL EXPLICIT TRADE MANPOWER & LABOR (₹): | G16: =SUM(G6:G15) -> 753.56721 | I16: =SUM(I6:I15) -> 619950.16
A18: ⚖️ FLAT BENCHMARK LABOR RECONCILIATION AUDIT (1 - 2% TOLERANCE)
A19: Flat Benchmark Labor Cost (@ ₹377.40 / sq ft): | G19: ='Project Summary & BOQ'!D6*'Settings & Rates'!$B$97 -> 566100
A20: Explicit Itemized Trade Labor Cost: | G20: =I16 -> 619950.16
A21: Labor Variance Amount (₹): | G21: =ABS(G20-G19) -> 53850.161
A22: Labor Variance Percentage (%): | G22: =G21/G19 -> 0.09512482
A23: Reconciliation Audit Status: | G23: =IF(G22<='Settings & Rates'!B56, "✔️ PASS (Within 2.0% Tolerance)", "⚠️ AUDIT REQUIRED") -> ⚠️ AUDIT REQUIRED

Sheet Trade Packages (Tier 2)
A1: 📦 TIER 2 - MESO TRADE-PACKAGE COST MODEL
A3: Project Built-up Area: | B3: ='Project Summary & BOQ'!D6 -> 1500 | C3: sq ft
A5: Package No. | B5: Trade Package Name | C5: Governing Scope | D5: Unit | E5: Package Rate (₹/sqft) | F5: Total Package Cost (₹) | G5: Share (%)
A6: 1 | B6: Civil Work Structure (RCC, Masonry, Shuttering) | C6: ='Project Summary & BOQ'!D6 -> 1500 | D6: sq ft | E6: ='Settings & Rates'!B11 -> 751.25 | F6: =C6*E6 -> 1126875 | G6: =F6/$F$14 -> 0.42360338
A7: 2 | B7: Finishing Works (Plaster, Flooring, Paint, POP) | C7: ='Project Summary & BOQ'!D6 -> 1500 | D7: sq ft | E7: ='Settings & Rates'!B12 -> 467.5 | F7: =C7*E7 -> 701250 | G7: =F7/$F$14 -> 0.26360676
A8: 3 | B8: Electrical Wiring, Switches & Conduit | C8: ='Project Summary & BOQ'!D6 -> 1500 | D8: sq ft | E8: ='Settings & Rates'!B13 -> 133 | F8: =C8*E8 -> 199500 | G8: =F8/$F$14 -> 0.074994009
A9: 4 | B9: Plumbing, Sanitaryware & Drainage | C9: ='Project Summary & BOQ'!D6 -> 1500 | D9: sq ft | E9: ='Settings & Rates'!B14 -> 126 | F9: =C9*E9 -> 189000 | G9: =F9/$F$14 -> 0.071046956
A10: 5 | B10: Fire Fighting & Safety Provisions | C10: ='Project Summary & BOQ'!D6 -> 1500 | D10: sq ft | E10: ='Settings & Rates'!B15 -> 40 | F10: =C10*E10 -> 60000 | G10: =F10/$F$14 -> 0.022554589
A11: 6 | B11: External Development & Landscaping | C11: ='Project Summary & BOQ'!D6 -> 1500 | D11: sq ft | E11: ='Settings & Rates'!B16 -> 94.5 | F11: =C11*E11 -> 141750 | G11: =F11/$F$14 -> 0.053285217
A12: DIRECT TRADE PACKAGES SUBTOTAL (₹): | F12: =SUM(F6:F11) -> 2418375 | G12: =F12/$F$14 -> 0.90909091
A13: Contractor Overhead & Profit (COP 10%): | F13: =F12*'Settings & Rates'!B17 -> 241837.5 | G13: =F13/$F$14 -> 0.090909091
A14: TOTAL TIER 2 TRADE-PACKAGE ESTIMATE (₹): | F14: =F12+F13 -> 2660212.5 | G14: 100.0%

Sheet Settings & Rates
A1: ⚙️ CIVIL ENGINEERING ESTIMATOR - UNIT RATES & COEFFICIENTS CONFIGURATION
A3: 1. Construction Quality Tiers (₹ / sq ft)
A4: Tier | B4: Rate (₹/sqft) | C4: Key / Code | D4: Description
A5: Basic (C-Class) | B5: 1500 | C5: Tier_Basic | D5: Standard low-cost residential structure
A6: Standard (B-Class) | B6: 1800 | C6: Tier_Standard | D6: Quality Indian urban residential construction (Default)
A7: Premium (A-Class) | B7: 2400 | C7: Tier_Premium | D7: High-end luxury finishes and branded fixtures
A9: 2. Trade Package Unit Rates (₹ / sq ft)
A10: Trade Package | B10: Rate (₹/sqft) | C10: Key / Code | D10: Scope of Work
A11: Civil Structure | B11: 751.25 | C11: Pkg_Civil | D11: Footings, Columns, Beams, Slabs, Masonry, Shuttering
A12: Finishing Work | B12: 467.5 | C12: Pkg_Finish | D12: Internal/External Plaster, Flooring, Painting, POP
A13: Electrical Works | B13: 133 | C13: Pkg_Elec | D13: Conduits, Wiring, DBs, Switches, Lighting Points
A14: Plumbing & Drainage | B14: 126 | C14: Pkg_Plumb | D14: Piping, Sanware, Water Tanks, Soil/Waste lines
A15: Fire Fighting | B15: 40 | C15: Pkg_Fire | D15: Risers, Hydrants, Extinguishers, Detectors
A16: External Development | B16: 94.5 | C16: Pkg_ExtDev | D16: Boundary wall, Paving, Landscaping, Drainage
A17: Contractor Overhead & Profit (%) | B17: 0.1 | C17: Pkg_COP | D17: Standard 10% COP on direct trade subtotal
A19: 3. Material Market Unit Rates
A20: Material Name | B20: Unit Rate (₹) | C20: Billing Unit | D20: Reference Standards
A21: Structural Steel (TMT Fe500) | B21: 65 | C21: per kg | D21: IS 1786 High Yield Strength Deformed Bars
A22: Cement (OPC/PPC 50kg Bag) | B22: 380 | C22: per bag | D22: IS 269 / IS 1489 Standard Cement
A23: River / Coarse Sand | B23: 55 | C23: per cu ft | D23: Zone II Sand for RCC & Plastering
A24: Coarse Aggregate (20mm down) | B24: 45 | C24: per cu ft | D24: Graded Crushed Blue Granite Stone
A25: Common Clay Bricks | B25: 9 | C25: per brick | D25: Standard 9" x 4.25" x 2.75" Class I Bricks
A26: Flooring Tiles (Vitrified) | B26: 65 | C26: per sq ft | D26: 600x600 mm Double Charged Vitrified Tiles
A27: Formwork / Shuttering | B27: 60 | C27: per sq ft | D27: Marine Ply & MS Prop Shuttering hire rate
A28: Flooring Mortar / Adhesive | B28: 40 | C28: per sq ft | D28: Base bedding and polymer grout
A29: Joinery & Doors/Windows | B29: 130 | C29: per sq ft | D29: Flush doors, UPVC/Aluminium windows
A30: Internal Wall Painting (Material) | B30: 70 | C30: per sq ft | D30: Putty (2 coats) + Primer (1) + Acrylic Emulsion (2)
A32: 4. Daily Labor Wage Rates (₹ / 8-hr Shift)
A33: Artisan Trade / Skill | B33: Daily Wage (₹) | C33: Role Code | D33: Skill Level
A34: Head Mason (Mistri) | B34: 950 | C34: Wage_Mason | D34: Skilled (RCC, Brickwork, Plaster, Tiling)
A35: Bar Bender / Steel Fitter | B35: 900 | C35: Wage_Bar | D35: Skilled (Cutting, Bending, Tying Fe500)
A36: Carpenter / Formwork Fitter | B36: 900 | C36: Wage_Carp | D36: Skilled (Ply erection, Shuttering props)
A37: Painter | B37: 850 | C37: Wage_Paint | D37: Skilled (Surface prep, Putty, Emulsion application)
A38: Electrician | B38: 900 | C38: Wage_Elec | D38: Skilled (Conduit chasing, Wire pulling, DB)
A39: Plumber | B39: 900 | C39: Wage_Plumb | D39: Skilled (Piping, Core cutting, Sanitaryware)
A40: Helper / Beldar / Mazdoor | B40: 600 | C40: Wage_Helper | D40: Unskilled (Material handling, Mortar mixing)
A41: JCB 3DX Excavator & Operator | B41: 1400 | C41: Wage_JCB_Hr | D41: Plant & Machinery Hourly Rental (₹/hr)
A43: 5. Daily Manpower Productivity Standards
A44: Activity / Trade | B44: Output per Day | C44: Output Unit | D44: Crew Composition
A45: Concrete Pouring (Skilled) | B45: 0.24 | C45: mandays / m³ | D45: Masons per m³ ready/batch mix concrete
...
