Workbook

Sheet Estimator
A1: CPWD Plinth Area Rate Estimator — 2025
A2: Blue-on-yellow cells = your inputs. All rates/percentages are pulled live by formula from sheets "01 Building Cost" through "07 Specialized E&M" — nothing is retyped. Green text = a value copied from another section of this sheet. Per source Note 1: all rates are inclusive of CP&OH, GST and Labour Welfare Cess; any other local Cess/Levy must be added separately (see input near the Grand Total).
A4: A. PROJECT & BUILDING BASICS
A5: Item | B5: Your input | C5: Unit | D5: Source condition / notes
A6: Building category | B6: Offices/Colleges | D6: Finest category available across sheets 01 & 02. For Section-1 lookups this maps down to the 4-category split used in sheet "01 Building Cost" (that sheet does not split Hostels/Quarters further).
A7: Structure type | B7: RCC Framed | D7: Governs base rate (1.1/1.2) and stronger-foundation rate (1.3.5).
A8: Typical (normal) floor height selected | B8: 3.6 | C8: metre | D8: Selects which base-rate row (3.60 m or 3.00 m) applies. Must equal 3.60 or 3.00 exactly, per source rate bands.
A9: Actual average floor height (typical floors) | B9: 3.6 | C9: metre | D9: Used for item 1.3.2 (extra/deduct per 0.3 m vs the normal height selected above).
A10: Number of storeys (including ground floor) | B10: 1 | D10: E.g. G+5 = 6. Base rate (1.1/1.2) covers upto six storeys; storeys beyond 6 attract item 1.3.1 extra (Section C below).
A11: Ground floor plinth area | B11: 0 | C11: sqm | D11: Used wherever source says "ground floor area only": items 1.3.3, 1.3.4, 1.3.5, 1.3.6, 1.3.7, 1.3.8.
A12: Total plinth area, all floors | B12: 0 | C12: sqm | D12: Sum of plinth area of every floor. Used for the base building-cost rate and as the default "applicable area" for extras unless overridden below.
A13: Plot area | B13: 0 | C13: sqm | D13: Used by Section 7 (external CCTV surveillance, street lighting) and available for Section 6 detailed site-development inputs.
A15: B. SECTION 1 — BASE BUILDING-COST RATE (auto-derived, then looked up)
A16: Item | B16: Derived value | C16: Unit | D16: How it is derived
A17: Category as used in sheet "01 Building Cost" (4-way split) | B17: =IF(OR($B$6="Hostels - with attached toilets",$B$6="Hostels - with common toilets",$B$6="Quarters"),"Hostels/Quarters",$B$6) -> Offices/Colleges | D17: Sheet 01 only distinguishes Offices/Colleges, Hospitals, Schools, Hostels/Quarters — the three finer categories above all fall under "Hostels/Quarters" there.
A18: Structure label as used in sheet "01 Building Cost" | B18: =IF($B$7="RCC Framed","RCC FRAMED STRUCTURE (Upto six storeys)","COMPOSITE (PARTIALLY LOAD BEARING AND PARTIALLY RCC FRAMED) STRUCTURE (Upto six storeys)") -> RCC FRAMED STRUCTURE (Upto six storeys)
A19: Floor-height condition text as used in sheet "01 Building Cost" | B19: ="Floor height "&TEXT($B$8,"0.00")&" metre" -> Floor height 3.60 metre
A21: Base rate (items 1.1 / 1.2) — matched from sheet 01 | B21: =IF(SUMPRODUCT((EXACT('01 Building Cost'!$B$5:$B$40,$B$18))*(EXACT('01 Building Cost'!$C$5:$C$40,$B$19))*(EXACT('01 Building Cost'!$D$5:$D$40,$B$17))*('01 Building Cost'!$F$5:$F$40<>""))=0,"N/A - no source rate for this combination",SUMPRODUCT((EXACT('01 Building Cost'!$B$5:$B$40,$B$18))*(EXACT('01 Building Cost'!$C$5:$C$40,$B$19))*(EXACT('01 Building Cost'!$D$5:$D$40,$B$17))*'01 Building Cost'!$F$5:$F$40)) -> 30920 | C21: ₹/sqm | D21: Looked up from sheet "01 Building Cost" by exact match on structure type, floor height and building category. If the source has no rate for this exact combination, shows "N/A" instead of a wrong zero.
A22: Base building cost = base rate × total plinth area | B22: =IF(ISNUMBER($B$21),$B$21*$B$12,0) -> 0 | C22: ₹
A24: C. SECTION 1 — ITEM 1.3.1: EXTRA FOR ADDITIONAL STOREYS BEYOND SIX
A25: Per sheet 01 note: base rate covers upto 6 storeys. Storeys 7-12 attract +1x the item-1.3.1 rate on their combined plinth area, storeys 13-18 attract +2x, 19-24 attract +3x, and so on (rate increases by 1x per additional 6-storey band). Default area per band assumes uniform floor plates (Total plinth area ÷ storeys × storeys in that band) — override column F if your floors are not uniform.
A26: Band | B26: Storey range | C26: Storeys in this band | D26: Band rate ₹/sqm | E26: Area (sqm) — override if not uniform | F26: Cost (₹)
A27: Band 1 | B27: =7&"-"&12 -> 7-12 | C27: =MAX(0,MIN($B$10,12)-7+1) -> 0 | D27: ='01 Building Cost'!$F$21*1 -> 123 | E27: =IF($B$10=0,0,C27*($B$12/$B$10)) -> 0 | F27: =IF(C27=0,0,D27*E27) -> 0
A28: Band 2 | B28: =13&"-"&18 -> 13-18 | C28: =MAX(0,MIN($B$10,18)-13+1) -> 0 | D28: ='01 Building Cost'!$F$21*2 -> 246 | E28: =IF($B$10=0,0,C28*($B$12/$B$10)) -> 0 | F28: =IF(C28=0,0,D28*E28) -> 0
A29: Band 3 | B29: =19&"-"&24 -> 19-24 | C29: =MAX(0,MIN($B$10,24)-19+1) -> 0 | D29: ='01 Building Cost'!$F$21*3 -> 369 | E29: =IF($B$10=0,0,C29*($B$12/$B$10)) -> 0 | F29: =IF(C29=0,0,D29*E29) -> 0
A30: Band 4 | B30: =25&"-"&30 -> 25-30 | C30: =MAX(0,MIN($B$10,30)-25+1) -> 0 | D30: ='01 Building Cost'!$F$21*4 -> 492 | E30: =IF($B$10=0,0,C30*($B$12/$B$10)) -> 0 | F30: =IF(C30=0,0,D30*E30) -> 0
A31: Band 5 | B31: =31&"-"&36 -> 31-36 | C31: =MAX(0,MIN($B$10,36)-31+1) -> 0 | D31: ='01 Building Cost'!$F$21*5 -> 615 | E31: =IF($B$10=0,0,C31*($B$12/$B$10)) -> 0 | F31: =IF(C31=0,0,D31*E31) -> 0
A32: Band 6 | B32: =37&"-"&42 -> 37-42 | C32: =MAX(0,MIN($B$10,42)-37+1) -> 0 | D32: ='01 Building Cost'!$F$21*6 -> 738 | E32: =IF($B$10=0,0,C32*($B$12/$B$10)) -> 0 | F32: =IF(C32=0,0,D32*E32) -> 0
A33: Band 7 | B33: =43&"-"&48 -> 43-48 | C33: =MAX(0,MIN($B$10,48)-43+1) -> 0 | D33: ='01 Building Cost'!$F$21*7 -> 861 | E33: =IF($B$10=0,0,C33*($B$12/$B$10)) -> 0 | F33: =IF(C33=0,0,D33*E33) -> 0
A34: Band 8 | B34: =49&"-"&54 -> 49-54 | C34: =MAX(0,MIN($B$10,54)-49+1) -> 0 | D34: ='01 Building Cost'!$F$21*8 -> 984 | E34: =IF($B$10=0,0,C34*($B$12/$B$10)) -> 0 | F34: =IF(C34=0,0,D34*E34) -> 0
A35: Band 9 | B35: =55&"-"&60 -> 55-60 | C35: =MAX(0,MIN($B$10,60)-55+1) -> 0 | D35: ='01 Building Cost'!$F$21*9 -> 1107 | E35: =IF($B$10=0,0,C35*($B$12/$B$10)) -> 0 | F35: =IF(C35=0,0,D35*E35) -> 0
A36: Band 10 | B36: =61&"-"&66 -> 61-66 | C36: =MAX(0,MIN($B$10,66)-61+1) -> 0 | D36: ='01 Building Cost'!$F$21*10 -> 1230 | E36: =IF($B$10=0,0,C36*($B$12/$B$10)) -> 0 | F36: =IF(C36=0,0,D36*E36) -> 0
A37: Total — item 1.3.1 (storey-band extra) | F37: =SUM(F27:F36) -> 0
A39: D. SECTION 1 — FOUNDATION / HEIGHT / BASEMENT / STILT / FIRE EXTRAS
A40: Item (source ref.) | B40: Input 1 | C40: Input 2 (area, where needed) | D40: Source condition | E40: Unit | F40: Cost (₹)
A41: 1.3.2 Extra/deduct — floor height ≠ normal height | B41: (uses actual vs normal height entered in Section A) | C41: =$B$12 -> 0 | D41: ='01 Building Cost'!C22 -> Every 0.3 metre or part thereof, additional / less height of floor above normal floor height of 3.60 metre / 3.00 metre | E41: ₹/sqm | F41: =IF(($B$9-$B$8)>=0,1,-1)*ROUNDUP(ABS(($B$9-$B$8))/0.3,0)*'01 Building Cost'!$F$22*C41 -> 0
A42: 1.3.3 Extra — higher plinth height (ground floor area only) | B42: 0.6 | C42: =$B$11 -> 0 | D42: ='01 Building Cost'!C23 -> Every 0.3 metre or part thereof, higher plinth height over normal plinth height of 0.60 metre (ground floor area only) | E42: actual plinth ht, m | F42: =IF(($B$42-0.6)>=0,1,-1)*ROUNDUP(ABS(($B$42-0.6))/0.3,0)*'01 Building Cost'!$F$23*C42 -> 0
A43: 1.3.4 Extra — deeper foundation (ground floor area only) | B43: 1.2 | C43: =$B$11 -> 0 | D43: ='01 Building Cost'!C24 -> Every 0.30 metre or part thereof, deeper foundations over normal depth of 1.20 metre (ground floor area only) | E43: actual depth, m | F43: =IF(($B$43-1.2)>=0,1,-1)*ROUNDUP(ABS(($B$43-1.2))/0.3,0)*'01 Building Cost'!$F$24*C43 -> 0
A44: 1.3.5 Stronger foundation for a future additional floor (ground floor area only) | B44: No | C44: =$B$11 -> 0 | D44: ='01 Building Cost'!C25 -> Making stronger foundations to take load of one additional floor at a later date (ground floor area only) | E44: rate depends on structure type | F44: =IF($B$44="Yes",IF($B$7="RCC Framed",'01 Building Cost'!$F$25,'01 Building Cost'!$F$26)*C44,0) -> 0
A45: 1.3.6 RCC raft foundation (ground floor area only) | B45: No | C45: =$B$11 -> 0 | D45: ='01 Building Cost'!B27&" — "&'01 Building Cost'!C27 -> RCC raft foundation — Ground floor area only | F45: =IF($B$45="Yes",'01 Building Cost'!$F$27*C45,0) -> 0
...

Sheet 01 Building Cost
A1: 01 — Building Cost
A2: Source section 1.0; specifications as per Annexure-I.
A4: Item No. | B4: Category | C4: Description / condition | D4: Building type / applicability | E4: Rate unit | F4: Rate
A5: 1.1.1 | B5: RCC FRAMED STRUCTURE (Upto six storeys) | C5: Floor height 3.60 metre | D5: Offices/Colleges | E5: ₹/sqm | F5: 30920
A6: 1.1.1 | B6: RCC FRAMED STRUCTURE (Upto six storeys) | C6: Floor height 3.60 metre | D6: Hospitals | E6: ₹/sqm | F6: 31990
A7: 1.1.1 | B7: RCC FRAMED STRUCTURE (Upto six storeys) | C7: Floor height 3.60 metre | D7: Schools | E7: ₹/sqm | F7: 23530
A8: 1.1.1 | B8: RCC FRAMED STRUCTURE (Upto six storeys) | C8: Floor height 3.60 metre | D8: Hostels/Quarters | E8: ₹/sqm
A9: 1.1.2 | B9: RCC FRAMED STRUCTURE (Upto six storeys) | C9: Floor height 3.00 metre | D9: Offices/Colleges | E9: ₹/sqm
A10: 1.1.2 | B10: RCC FRAMED STRUCTURE (Upto six storeys) | C10: Floor height 3.00 metre | D10: Hospitals | E10: ₹/sqm
A11: 1.1.2 | B11: RCC FRAMED STRUCTURE (Upto six storeys) | C11: Floor height 3.00 metre | D11: Schools | E11: ₹/sqm
A12: 1.1.2 | B12: RCC FRAMED STRUCTURE (Upto six storeys) | C12: Floor height 3.00 metre | D12: Hostels/Quarters | E12: ₹/sqm | F12: 24410
A13: 1.2.1 | B13: COMPOSITE (PARTIALLY LOAD BEARING AND PARTIALLY RCC FRAMED) STRUCTURE (Upto six storeys) | C13: Floor height 3.60 metre | D13: Offices/Colleges | E13: ₹/sqm | F13: 26280
A14: 1.2.1 | B14: COMPOSITE (PARTIALLY LOAD BEARING AND PARTIALLY RCC FRAMED) STRUCTURE (Upto six storeys) | C14: Floor height 3.60 metre | D14: Hospitals | E14: ₹/sqm | F14: 27190
A15: 1.2.1 | B15: COMPOSITE (PARTIALLY LOAD BEARING AND PARTIALLY RCC FRAMED) STRUCTURE (Upto six storeys) | C15: Floor height 3.60 metre | D15: Schools | E15: ₹/sqm | F15: 20000
A16: 1.2.1 | B16: COMPOSITE (PARTIALLY LOAD BEARING AND PARTIALLY RCC FRAMED) STRUCTURE (Upto six storeys) | C16: Floor height 3.60 metre | D16: Hostels/Quarters | E16: ₹/sqm
A17: 1.2.2 | B17: COMPOSITE (PARTIALLY LOAD BEARING AND PARTIALLY RCC FRAMED) STRUCTURE (Upto six storeys) | C17: Floor height 3.00 metre | D17: Offices/Colleges | E17: ₹/sqm
A18: 1.2.2 | B18: COMPOSITE (PARTIALLY LOAD BEARING AND PARTIALLY RCC FRAMED) STRUCTURE (Upto six storeys) | C18: Floor height 3.00 metre | D18: Hospitals | E18: ₹/sqm
A19: 1.2.2 | B19: COMPOSITE (PARTIALLY LOAD BEARING AND PARTIALLY RCC FRAMED) STRUCTURE (Upto six storeys) | C19: Floor height 3.00 metre | D19: Schools | E19: ₹/sqm
A20: 1.2.2 | B20: COMPOSITE (PARTIALLY LOAD BEARING AND PARTIALLY RCC FRAMED) STRUCTURE (Upto six storeys) | C20: Floor height 3.00 metre | D20: Hostels/Quarters | E20: ₹/sqm | F20: 20750
A21: 1.3.1 | B21: EXTRA FOR | C21: Set of six additional storey (7th to 12th storey) | D21: All applicable | E21: ₹/sqm | F21: 123
A22: 1.3.2 | B22: EXTRA FOR | C22: Every 0.3 metre or part thereof, additional / less height of floor above normal floor height of 3.60 metre / 3.00 metre | D22: Applicable area | E22: ₹/sqm | F22: 434
A23: 1.3.3 | B23: EXTRA FOR | C23: Every 0.3 metre or part thereof, higher plinth height over normal plinth height of 0.60 metre (ground floor area only) | D23: Applicable area | E23: ₹/sqm | F23: 470
A24: 1.3.4 | B24: EXTRA FOR | C24: Every 0.30 metre or part thereof, deeper foundations over normal depth of 1.20 metre (ground floor area only) | D24: Applicable area | E24: ₹/sqm | F24: 205
A25: 1.3.5 | B25: EXTRA FOR | C25: Making stronger foundations to take load of one additional floor at a later date (ground floor area only) | D25: RCC framed structures | E25: ₹/sqm | F25: 1800
A26: 1.3.5 | B26: EXTRA FOR | C26: Making stronger foundations to take load of one additional floor at a later date (ground floor area only) | D26: Composite structure | E26: ₹/sqm | F26: 700
A27: 1.3.6 | B27: RCC raft foundation | C27: Ground floor area only | D27: All applicable | E27: ₹/sqm | F27: 12765
A28: 1.3.7 | B28: Pile foundation upto a depth of 15 metre | C28: Ground floor area only | D28: All applicable | E28: ₹/sqm | F28: 22240
A29: 1.3.8 | B29: Every 1.0 m deeper pile foundation over normal depth of 15 metre | C29: Ground floor area only | D29: All applicable | E29: ₹/sqm | F29: 2265
A30: 1.3.9 | B30: Stronger structural members to take heavy load above 500 kg per sqm upto 1000 kg per sqm | C30: Applicable area | D30: All applicable | E30: ₹/sqm | F30: 2070
A31: 1.4.1 | B31: BASEMENT FLOOR | C31: Floor height upto 3.35 metre including water proofing (excluding raft base) | D31: All applicable | E31: ₹/sqm | F31: 23170
... A40: 1.8.2 | B40: STILT PORTION | C40: Every 0.30 metre additional height above 3.60 metre | D40: Applicable stilt area | E40: ₹/sqm | F40: 235
A43: Note: | B43: 1.3.1 Extra for additional storeys
B44: An additional rate of ₹123/sqm shall apply to each set of six additional storeys, as follows:
B45: 7th to 12th storey: ₹123/sqm
B46: 13th to 18th storey: ₹246/sqm
B47: 19th to 24th storey: ₹369/sqm
B48: 25th to 30th storey: ₹492/sqm
B49: And so on, with the rate increasing by ₹123/sqm for each successive set of six storeys.
B50: The applicable plinth area shall be the total plinth area of all storeys within the respective set of six storeys.
B51: If the final set contains fewer than six storeys, the same procedure shall apply.
...

Sheet 02 Services
A1: 02 — Services
A2: Percentage rates; the source states the percentage is based on building cost as per 1.0, excluding specified subheads.
A4: Item No. | B4: Description | C4: Building type / condition | D4: Rate basis | E4: Rate (%)
A5: 2.1 | B5: Internal water supply & sanitary installations | C5: Offices/Colleges | D5: % of building cost | E5: 4
A6: 2.1 | B6: Internal water supply & sanitary installations | C6: Hospitals | D6: % of building cost | E6: 10
A7: 2.1 | B7: Internal water supply & sanitary installations | C7: Schools | D7: % of building cost | E7: 5
A8: 2.1 | B8: Internal water supply & sanitary installations | C8: Hostels — with attached toilets | D8: % of building cost | E8: 12
A9: 2.1 | B9: Internal water supply & sanitary installations | C9: Hostels — with common toilets | D9: % of building cost | E9: 8
A10: 2.1 | B10: Internal water supply & sanitary installations | C10: Quarters | D10: % of building cost | E10: 9
A11: 2.2.1 | B11: Electrical external service connections | C11: All building categories | D11: % of building cost | E11: 3.75
A12: 2.2.2 | B12: Civil external service connections | C12: All building categories | D12: % of building cost | E12: 1.25
A13: 2.2.3 | B13: Local body approvals including tree cutting etc. | C13: All building categories | D13: % of building cost | E13: 1.25
A14: 2.3 | B14: Internal electric installations | C14: All building categories | D14: % of building cost | E14: 12.5
A15: 2.4.1 | B15: Power wiring and plugs | C15: All building categories | D15: % of building cost | E15: 4
A16: 2.4.2 | B16: Lightning conductors | C16: Offices/Colleges | D16: % of building cost | E16: 0.25
... A19: 2.4.2 | B19: Lightning conductors | C19: Hostels | D19: % of building cost | E19: 0.25
A20: 2.4.2 | B20: Lightning conductors | C20: Quarters | D20: % of building cost
A21: 2.4.3 | B21: Telephone conduits | C21: Offices/Colleges | D21: % of building cost | E21: 0.25
A22: 2.4.3 | B22: Telephone conduits | C22: Hospitals | D22: % of building cost | E22: 0.25
A23: 2.4.3 | B23: Telephone conduits | C23: Schools | D23: % of building cost | E23: 0.25
A24: 2.4.3 | B24: Telephone conduits | C24: Hostels | D24: % of building cost | E24: 0.25
A25: 2.4.3 | B25: Telephone conduits | C25: Quarters | D25: % of building cost
A27: Source basis note
A28: For section 2.0, the source states that percentages refer to the percentage of building cost as per 1.0 above, excluding subheads 1.3.4, 1.3.5, 1.3.6, 1.3.7, 1.3.8, 1.3.9, 1.5 and 1.6.

Sheet 03 TPQA Consultancy
A1: 03 — TPQA & Consultancy Services
A2: Percentages refer to building cost (sum of section 1.0 and section 2.0).
A4: Item No. | B4: Description | C4: Applicability | D4: Rate basis | E4: Rate (%)
A5: 3.1 | B5: Third Party Quality Assurance | C5: All building categories | D5: % of building cost (1.0 + 2.0) | E5: 1
A6: 3.2 | B6: Consultancy Services for Architectural, Structural and MEP Services, if outsourced | C6: All building categories | D6: % of building cost (1.0 + 2.0) | E6: 1.75

Sheet 04 Lifts
A1: 04 — Lifts
A2: Power-operated centre-opening doors and AC variable voltage & variable frequency controls.
A4: Item No. | B4: Lift type | C4: Capacity / persons | D4: Speed (m/sec) | E4: Travel height | F4: Price (₹ lakh) | G4: Extra per additional floor (₹) | H4: Baseline floors incl. ground (derived) | I4: Spec label (for dropdown)
A5: 4.1.1 | B5: Passenger | C5: 8 | D5: 1.0 | E5: G+4 | F5: 17.24 | G5: 99860 | H5: =VALUE(MID(E5,FIND("+",E5)+1,10))+1 -> 5 | I5: =B5&" "&C5&"-person, "&D5&" m/s, "&E5 -> Passenger 8-person, 1.0 m/s, G+4
A6: 4.1.2 | B6: Passenger | C6: 8 | D6: 1.5 | E6: G+5 | F6: 19.39 | G6: 99860 | H6: =VALUE(MID(E6,FIND("+",E6)+1,10))+1 -> 6 | I6: =B6&" "&C6&"-person, "&D6&" m/s, "&E6 -> Passenger 8-person, 1.5 m/s, G+5
A7: 4.1.3 | B7: Passenger | C7: 13 | D7: 1.0 | E7: G+4 | F7: 19.39 | G7: 99860 | H7: =VALUE(MID(E7,FIND("+",E7)+1,10))+1 -> 5 | I7: =B7&" "&C7&"-person, "&D7&" m/s, "&E7 -> Passenger 13-person, 1.0 m/s, G+4
A8: 4.1.4 | B8: Passenger | C8: 13 | D8: 1.5 | E8: G+5 | F8: 21.55 | G8: 122050 | H8: =VALUE(MID(E8,FIND("+",E8)+1,10))+1 -> 6 | I8: =B8&" "&C8&"-person, "&D8&" m/s, "&E8 -> Passenger 13-person, 1.5 m/s, G+5
A9: 4.1.5 | B9: Passenger | C9: 16 | D9: 1.0 | E9: G+4 | F9: 25.85 | G9: 122050 | H9: =VALUE(MID(E9,FIND("+",E9)+1,10))+1 -> 5 | I9: =B9&" "&C9&"-person, "&D9&" m/s, "&E9 -> Passenger 16-person, 1.0 m/s, G+4
A10: 4.1.6 | B10: Passenger | C10: 16 | D10: 1.5 | E10: G+5 | F10: 28.01 | G10: 122050 | H10: =VALUE(MID(E10,FIND("+",E10)+1,10))+1 -> 6 | I10: =B10&" "&C10&"-person, "&D10&" m/s, "&E10 -> Passenger 16-person, 1.5 m/s, G+5
A11: 4.1.7 | B11: Passenger | C11: 16 | D11: 2.5 | E11: G+12 | F11: 75.41 | G11: 122050 | H11: =VALUE(MID(E11,FIND("+",E11)+1,10))+1 -> 13 | I11: =B11&" "&C11&"-person, "&D11&" m/s, "&E11 -> Passenger 16-person, 2.5 m/s, G+12
A12: 4.2.1 | B12: Bed | C12: 20 | D12: 0.75 | E12: G+4 | F12: 25.85 | G12: 122050 | H12: =VALUE(MID(E12,FIND("+",E12)+1,10))+1 -> 5 | I12: =B12&" "&C12&"-person, "&D12&" m/s, "&E12 -> Bed 20-person, 0.75 m/s, G+4
A13: 4.2.2 | B13: Bed | C13: 20 | D13: 1.5 | E13: G+5 | F13: 29.09 | G13: 122050 | H13: =VALUE(MID(E13,FIND("+",E13)+1,10))+1 -> 6 | I13: =B13&" "&C13&"-person, "&D13&" m/s, "&E13 -> Bed 20-person, 1.5 m/s, G+5
A14: 4.2.3 | B14: Bed | C14: 20 | D14: 2.5 | E14: G+12 | F14: 80.79 | G14: 122050 | H14: =VALUE(MID(E14,FIND("+",E14)+1,10))+1 -> 13 | I14: =B14&" "&C14&"-person, "&D14&" m/s, "&E14 -> Bed 20-person, 2.5 m/s, G+12
A15: 4.3.1 | B15: Goods (2 speed) | C15: 1 Ton | D15: 0.5 | E15: G+4 | F15: 28.01 | G15: 94310 | H15: =VALUE(MID(E15,FIND("+",E15)+1,10))+1 -> 5 | I15: =B15&" "&C15&"-person, "&D15&" m/s, "&E15 -> Goods (2 speed) 1 Ton-person, 0.5 m/s, G+4
A16: 4.3.2 | B16: Goods (2 speed) | C16: 2 Ton | D16: 0.5 | E16: G+4 | F16: 35.55 | G16: 94310 | H16: =VALUE(MID(E16,FIND("+",E16)+1,10))+1 -> 5 | I16: =B16&" "&C16&"-person, "&D16&" m/s, "&E16 -> Goods (2 speed) 2 Ton-person, 0.5 m/s, G+4
A17: 4.3.3 | B17: Goods (2 speed) | C17: 3 Ton | D17: 0.25 | E17: G+4 | F17: 44.17 | G17: 110950 | H17: =VALUE(MID(E17,FIND("+",E17)+1,10))+1 -> 5 | I17: =B17&" "&C17&"-person, "&D17&" m/s, "&E17 -> Goods (2 speed) 3 Ton-person, 0.25 m/s, G+4

Sheet 05 RCC Water Tank
A1: 05 — RCC Water Tank
A2: Rates as stated in ₹ per litre.
A4: Item No. | B4: Description | C4: Rate unit | D4: Rate
A5: 5.1 | B5: Overhead tank without independent staging | C5: ₹/litre | D5: 23
A6: 5.2 | B6: Overhead tank with staging height upto 20 metre | C6: ₹/litre | D6: 35
A7: 5.3 | B7: Overhead tank with staging height above 20 metre upto 30 metre | C7: ₹/litre | D7: 40
A8: 5.4 | B8: Overhead tank with staging height above 30 metre upto 40 metre | C8: ₹/litre | D8: 47
A9: 5.5 | B9: Underground sump | C9: ₹/litre | D9: 24

Sheet 06 Development of Site
A1: 06 — Development of Site
A2: Rates are presented using the source units and descriptions.
A4: Item No. | B4: Description | C4: Rate unit | D4: Rate
A5: 6.1 | B5: Levelling | C5: ₹/sqm | D5: 160
A6: 6.2.1 | B6: Internal road with WBM and bituminous top | C6: ₹/sqm | D6: 1940
A7: 6.2.2 | B7: Internal road with WMM and bituminous top | C7: ₹/sqm | D7: 2150
A8: 6.2.3 | B8: Cement concrete pavement with vacuum dewatered concrete | C8: ₹/sqm | D8: 2945
A9: 6.2.4 | B9: Footpath with PCC base, 60 mm thick paver blocks and kerb stone edging | C9: ₹/sqm | D9: 2930
A10: 6.3 | B10: External sewerage | C10: ₹/metre | D10: 4180
A11: 6.4.1 | B11: Filtered water supply — Distribution lines upto 100 mm dia | C11: ₹/metre | D11: 2170
A12: 6.4.2 | B12: Filtered water supply — Peripheral grid 150 mm to 300 mm dia pipes | C12: ₹/metre | D12: 4175
A13: 6.4.3 | B13: Unfiltered water supply distribution lines | C13: ₹/metre | D13: 1560
A14: 6.5 | B14: Storm water drains | C14: ₹/metre | D14: 10810
A15: 6.6 | B15: Rain water harvesting (RWH) — excluding collection tank | C15: ₹/metre | D15: 2330
A16: 6.7 | B16: Trenches for services | C16: ₹/metre | D16: 7460
... A20: 6.9.2 | B20: Vertical plantations — excluding frame work; rate applicable on vertical gardening area | C20: ₹/sqm | D20: 6683

Sheet 07 Specialized E&M
A1: 07 — Specialized E&M Works
A2: Items 7.1 to 7.28 from the source PDF; descriptions retained and organized into a single rate table.
A4: Item No. | B4: Description / applicability | C4: Rate unit | D4: Rate
A5: 7.1.1 | B5: 33 kV receiving substation and 33 kV/11 kV HT cabling — complete specified system | C5: ₹/kVA | D5: 3800
A6: 7.2.1 | B6: 33 KV/0.433 KV substation equipment — complete specified system | C6: ₹/kVA | D6: 9000
A7: 7.2.2 | B7: 11 KV/0.433 KV substation equipment — complete specified system | C7: ₹/kVA | D7: 8100
A8: 7.3.1 | B8: Silent type DG sets, AMF panel, bus ducting/cables, synchronizing panel where required, enclosure works, earthing, fuel/exhaust systems and connected civil works | C8: ₹/kVA | D8: 11560
A9: 7.3.2 | B9: Extra for synchronizing panels wherever required | C9: ₹/kVA | D9: 1070
A10: 7.4.1 | B10: Online 3 phase UPS system with 30 minutes backup including batteries, cables, racks etc. | C10: ₹/kVA | D10: 21290
A11: 7.4.2 | B11: Add for every additional 30 minutes backup | C11: ₹/kVA | D11: 9580
A12: 7.5.1 | B12: Energy efficient central AC plant including low side works | C12: ₹/TR | D12: 90380
A13: 7.5.2 | B13: Extra for stand-by chilling units high side | C13: ₹/TR | D13: 40860
A14: 7.6.1 | B14: VRV/VRF system including indoor/outdoor units, piping, electrical power distribution/wiring, electrical panel, treated fresh air system etc. | C14: ₹/HP | D14: 58480
A15: 7.7.1 | B15: Precision air conditioning system including piping, electrical cabling, controller etc. | C15: ₹/TR | D15: 110000
A16: 7.8.1 | B16: Grid interactive roof top solar photovoltaic power generation system including space frame | C16: ₹/kWp | D16: 58480
... A43: 7.28 | B43: Motorized steel gates upto 6.00 metre width | C43: ₹/gate | D43: 500000
A49: Source notes embedded in the PDF
A50: 7.2: For kVA estimation, the source refers to the CPWD Guidelines for Substation & Power Distribution Systems of Buildings-2019, paras 4.4, 13 and other relevant paras.
A51: 7.10: CCTV indoor rate includes peripheral IP-based PTZ camera, indoor cameras at reception/corridors/lift lobby etc., wiring to CCTV room and monitoring unit(s); excludes inside office/lab rooms and special video walls.
A52: 7.17/7.18: Source notes that common switches, OFC and CAT 6A infrastructure may be economical for both voice and networking.
A53: 7.19 street lighting: Source says applicable for plot sizes more than 1 acre; for smaller plots actual requirements may be worked out.
A54: General façade lighting, if required, is to be assessed case by case.

Sheet 08 Notes
A1: 08 — Source Notes
A2: Notes reproduced/organized from the CPWD PDF; no external corrections substituted.
A4: Note | B4: Source note
A5: 1 | B5: Rates are inclusive of CP & OH, GST and Labour Welfare Cess; any other Cess/Levy imposed by local Government shall be added separately.
A6: 2 | B6: Third Party Quality Assurance (Item 3.1) and Consultancy Services for designing and planning of the project (Item 3.2) shall only be considered if desired by the clients.
A7: 3 | B7: Accessibility features for barrier-free built environment: for new construction, cost is deemed included in the rate for non-residential buildings; for existing construction, estimate may be prepared as per prevalent Delhi Schedule of Rates.
A8: 4.1 | B8: If development component area/length under items 6.1 to 6.7 cannot be computed: Compact site — 4.5% of building cost. Description: single huge-area building with few ancillary buildings or few high-rise blocks (higher than 12 storeys) in close cluster.
A9: 4.2 | B9: Semi compact/semi scattered site — 6.0% of building cost. Description: few midrise blocks (6 to 12 storeys) in a gated compound.
A10: 4.3 | B10: Large site — 7.5% of building cost. Description: various scattered low-rise buildings (upto 4 storeys), with exception of a block or two upto 6 storeys.
A11: 5a | B11: Development works not included: tube wells, pumps, open wells, treatment plant, extension of lines from source of local bodies, head works at water source etc.
A12: 5b | B12: Development works not included: sewage pumps, sewage treatment plants, septic tanks, extension of outfall sewer upto point of disposal etc.
A13: 6 | B13: Provision for Specialized E&M services, if required, may be made as per section 7.0.
A14: 7 | B14: Concealed wiring shall be used in all electrical works.
A15: 8a | B15: Green measure included in civil/electrical rates: over-deck insulation and high SRI reflective paint on thereof.
... A22: 8h | B22: Green measure included: BEE-certified 5-star rated fixtures.

Sheet 09 Cost Index
A1: 09 — Annexure-VI: Proforma for Calculation of Building Cost Index
A2: Component rates as presented in the PDF. The PDF's second page of the proforma labels the comparison rates as 01.04.2023.
A4: S.No. | B4: Description | C4: Unit | D4: %age | E4: Rates as on 01.04.2025 (₹) | F4: Proportionate value (₹) | G4: Weightage/combined rates (₹) | H4: Weightage of Component (%) | I4: Rates at revision of Cost Index | J4: Cost Index
A5: 1 | B5: Bricks (Fly Ash) | C5: 1000 nos. | D5: 100 | E5: 4750 | F5: 4750 | G5: 4750 | H5: 8
A6: 2 | B6: Cement (OPC) | C6: qtl. | D6: 100 | E6: 523.45 | F6: 523.45 | G6: 523.45 | H6: 14.5
A7: 3a | B7: TMT Steel Reinforcement bar — 8 & 10 mm dia. | C7: qtl. | D7: 50 | E7: 5430 | F7: 2715 | G7: 5530 | H7: 19.5
A8: 3b | B8: TMT Steel Reinforcement bar — 12 & 16 mm dia. | C8: qtl. | D8: 50 | E8: 5630 | F8: 2815
A9: 4a | B9: Aggregates 20 mm — Natural sources | C9: cum | D9: 75 | E9: 1500 | F9: 1125 | G9: 1375 | H9: 6.5
A10: 4b | B10: Aggregates 20 mm (RCA) | C10: cum | D10: 25 | E10: 1000 | F10: 250
A11: 5a | B11: Sand (coarse sand) — Natural sources | C11: cum | D11: 75 | E11: 1250 | F11: 937.5 | G11: 1260 | H11: 3
A12: 5b | B12: Sand (coarse sand) RA | C12: cum | D12: 25 | E12: 1290 | F12: 322.5
A13: 6a | B13: Flooring Items — Vitrified tiles | C13: sqm | D13: 50 | E13: 380 | F13: 190 | G13: 658.07 | H13: 5
A14: 6b | B14: Flooring Items — Ceramic tiles | C14: sqm | D14: 20 | E14: 352 | F14: 70.4
A15: 6c | B15: Flooring Items — Kota stone | C15: sqm | D15: 10 | E15: 376.74 | F15: 37.67
A16: 6d | B16: Flooring Items — Granite stone | C16: sqm | D16: 20 | E16: 1800 | F16: 360
A17: 7a | B17: Paints — Synthetic enamel paint | C17: litre | D17: 33.33 | E17: 178 | F17: 59.33 | G17: 167.67 | H17: 3
A18: 7b | B18: Paints — Acrylic washable distemper | C18: litre | D18: 33.33 | E18: 38 | F18: 12.67
A19: 7c | B19: Paints — Premium acrylic paint | C19: litre | D19: 33.33 | E19: 287 | F19: 95.66
A20: 8a | B20: Door/windows — 35 mm thick flush door shutters, both side commercial veneering | C20: sqm | D20: 30 | E20: 2120 | F20: 636 | G20: 2601 | H20: 7
A21: 8b | B21: Door/windows — Factory made, standard Z-section steel windows | C21: sqm | D21: 15 | E21: 1750 | F21: 262.5
A22: 8c | B22: Door/windows — uPVC windows | C22: sqm | D22: 20 | E22: 4400 | F22: 880
A23: 8d | B23: Door/windows — Aluminum window | C23: sqm | D23: 35 | E23: 2350 | F23: 822.5
A24: 9a | B24: Pipes — 15 mm GI pipes | C24: metre | D24: 10 | E24: 110 | F24: 11 | G24: 350 | H24: 2.5
A25: 9b | B25: Pipes — 100 mm CI pipes | C25: metre | D25: 40 | E25: 710 | F25: 284
A26: 9c | B26: Pipes — 20 mm black conduits | C26: metre | D26: 20 | E26: 80 | F26: 16
A27: 9d | B27: Pipes — 20 mm CPVC pipes | C27: metre | D27: 30 | E27: 130 | F27: 39
A28: 10a | B28: Lamps & Fans — Ceiling fans 1200 mm | C28: each | D28: 50 | E28: 1315 | F28: 657.5 | G28: 816.4 | H28: 4.5
A29: 10b | B29: Lamps & Fans — 1200 mm LED tube lights with fittings | C29: each | D29: 40 | E29: 383 | F29: 153.2
A30: 10c | B30: Lamps & Fans — LED bulbs 9/11 W | C30: each | D30: 10 | E30: 57 | F30: 5.7
A31: 11 | B31: Electrical machinery, Motor 7.5 HP (pump set) 1500 RPM | C31: each | D31: 100 | E31: 29500 | F31: 29500 | G31: 29500 | H31: 2.5
A32: 12a | B32: Wires & cables — Copper wire 1.5 sqmm | C32: 100 metre | D32: 70 | E32: 1280 | F32: 896 | G32: 1861.4 | H32: 4
A33: 12b | B33: Wires & cables — Copper wire 4.0 sqmm | C33: 100 metre | D33: 30 | E33: 3218 | F33: 965.4
A34: 13a | B34: Labour — Skilled | C34: each | D34: 50 | E34: 981 | F34: 490.5 | G34: 893 | H34: 20
A35: 13b | B35: Labour — Unskilled | C35: each | D35: 50 | E35: 805 | F35: 402.5
A38: Purpose: The Building Cost Index indicates the change in construction cost from the base period to the current period. It is calculated using weighted changes in the rates of representative construction materials, equipment and labour.
A40: Important source note
A41: The PDF notes that aggregates 20 mm and coarse sand are split into 75% natural source and 25% RCA/RA. Where RCA/RA components are unavailable because C&D waste conversion units are not set up, the 25% RCA/RA components may be avoided and 100% natural-source materials considered.
A42: The PDF also states that material rates adopted in column 5 and computed rates in columns 6 and 7 are bare rates excluding GST or other levy; for local cost index, bare rates at the respective station shall be considered.
A49: S.No. | B49: Description | C49: Unit | D49: %age | E49: Rate ₹ | F49: Proportionate value ₹ | G49: Weightage rate ₹ | H49: Component weight | I49: Rate at revision | J49: Cost Index
A50: 1 | B50: Bricks (Fly Ash) | C50: 1000 nos. | D50: 1 | E50: 4750 | F50: 4750 | G50: 4750 | H50: 0.08 | I50: — | J50: —
...

Sheet 10 Source Check
A1: 10 — Source Coverage & Verification Log
A2: Cross-check against all 11 pages of the supplied PDF. Blank cells mean the source does not provide a corresponding value in that row.
A4: Check area | B4: Finding | C4: Status | D4: PDF location
A5: Document identity | B5: Title: Plinth Area Rates 2025 | C5: Confirmed | D5: Page 1
A6: Effective date | B6: Rates as on 01.04.2025 | C6: Confirmed | D6: Page 1
A7: Unit convention | B7: Rate in ₹ per sqm for main PAR table | C7: Confirmed | D7: Page 1
A8: Section 1.0 | B8: Building Cost items 1.1–1.8 | C8: Included | D8: Pages 1–2
A9: Section 2.0 | B9: Services items 2.1–2.4 | C9: Included | D9: Pages 2–3
A10: Section 3.0 | B10: TPQA & Consultancy items 3.1–3.2 | C10: Included | D10: Page 3
A11: Section 4.0 | B11: Passenger, Bed and Goods lifts | C11: Included | D11: Pages 3–4
A12: Section 5.0 | B12: RCC Water Tank items 5.1–5.5 | C12: Included | D12: Page 4
A13: Section 6.0 | B13: Development of Site items 6.1–6.9.2 | C13: Included | D13: Pages 4–5
A14: Section 7.0 | B14: Specialized E&M items 7.1–7.28 | C14: Included | D14: Pages 5–8
A15: Notes | B15: Notes 1–8 and subnotes | C15: Included | D15: Page 9
... A21: No silent correction | B21: Values/descriptions were reorganized for Excel usability but not replaced with external values. | C21: Confirmed | D21: Entire document
